File: figures/Plastic_fig.csv
Radius (A°),Coil diameter (A°),Pitch angle (deg),Pitch length (A°),Number of turns,Total length (A°),Yield stress (GPa),Failure strain,Toughness (GPa)
8.23410722,6.992397394,30.64025471,30.64591669,1.667363874,51.09789437,1.54297896,0.015328352,0.000419352
6.55812625,5.166916835,27.04652866,21.03763347,1.00407588,21.12338033,2.729022025,0.014652676,0.013934981
8.898476723,7.225016024,27.06542821,28.56843349,0.650755271,18.59105867,2.290831011,0.052673251,0.02615236
9.293035929,6.158209519,41.01411331,50.78279357,1.365413455,69.33950962,4.531918767,0.099188534,0.055733858
6.438867063,9.251437012,21.29775689,15.77154265,2.409710561,38.00485288,3.111061485,0.125460281,0.116137849
4.772492604,5.397946739,45.29057585,30.29216135,1.0792371,32.69242438,9.111930446,0.02336569,0.246987443
7.841304582,5.273059854,33.33444601,32.40568723,0.714885554,23.16635767,5.856370764,0.635292101,0.346523877
6.476863153,8.036559131,44.26790111,39.66842471,1.174545308,46.5923621,3.430398204,0.294398146,0.473714337
8.543539134,6.96996581,23.80823908,23.68520448,1.065372801,25.23357263,2.043562493,0.295385586,0.607309335
10.72393484,8.296286131,7.915072214,9.36787987,2.029140352,19.00874305,3.546538727,0.072152217,0.857516178
9.557815991,8.174202958,25.63517571,28.81817565,0.890121545,25.65167904,2.337369311,0.371830683,1.133489672
4.992118171,8.778750094,53.01257117,41.6436306,2.55790006,106.5202452,15.13569762,0.176302415,1.369694447
7.192286272,7.425331844,36.79449626,33.80001907,1.73272534,58.56614955,10.44985321,0.283809434,1.426176897
3.62618608,3.495314511,49.55993918,26.7332153,9.061801443,242.251089,26.24051818,0.110199733,1.568806809
4.111971524,2.783950558,40.78215217,22.28723712,8.141400672,181.4493273,28.57366794,0.109288135,1.671444357
3.435767025,4.338340837,53.5415607,29.21821528,7.589161136,221.7417439,26.47225066,0.124801715,1.75590569
4.856715418,8.230849291,42.66204486,28.12161971,2.529437249,71.13187239,23.99122385,0.141082167,1.797349526
4.191181887,3.022892283,38.08693297,20.63877546,3.241527332,66.90115474,43.99328394,0.08121094,1.825687439
6.067752545,10.64358822,61.2849376,69.5929574,3.186613401,221.7658506,22.93015074,0.169923083,1.869546129
3.26633677,3.784889927,56.58225166,31.10379253,6.899360318,214.5962719,37.1233845,0.105138302,1.907884163
7.838492241,13.20254784,45.6622328,50.40255714,4.547380911,229.1996262,19.54535503,0.23998233,1.919517868
9.485272122,12.12536772,15.66961944,16.71807138,2.953972083,49.38471614,5.695381294,0.646553344,1.944955111
2.697141361,5.06387804,61.91460801,31.75771926,8.215857256,260.9168882,33.35158036,0.139973345,1.983826481
3.951386673,6.311100713,61.08577986,44.94819654,2.481210292,111.5259278,34.44997582,0.114507068,2.004801103
3.314050827,2.41023883,37.76760749,16.13296864,8.783798479,141.7087454,33.76093204,0.140161443,2.0401051
3.958877996,7.266458671,72.23563289,77.64043404,3.448339124,267.7305463,37.44693724,0.130316748,2.056357485
5.480557526,7.009769059,59.78200805,59.12315723,4.349720054,257.1691827,27.74523921,0.175448138,2.069505059
2.382195909,3.361871528,69.64457326,40.34317895,6.097881263,246.007915,43.80755986,0.090370813,2.084435816
4.025709115,5.724561716,63.74463116,51.27960452,3.037790308,155.7766856,32.99192638,0.129764188,2.097236511
3.424626435,3.864184275,63.83885773,43.80442884,4.377609871,191.7587001,39.50987955,0.115158194,2.116905504
3.113556238,3.430081752,63.74660075,39.66401029,6.441303152,255.4879145,44.80000797,0.089856541,2.127492957
3.388304079,4.468692949,47.64811409,23.35416009,2.106004652,49.18396978,10.48383747,0.055471237,2.144160079
4.36627302,3.04238531,61.05063503,49.59574755,4.979089631,246.9416723,44.56242326,0.145285463,2.154950658
8.031802637,8.643255303,14.74603163,13.28266833,3.03606444,40.32703699,5.547776131,0.735709282,2.17115665
3.38124733,3.749116245,66.03113277,47.78692359,4.752254041,227.0956007,28.6961689,0.129834368,2.179011469
4.00474336,4.774092028,48.89256454,28.83681122,7.403089977,213.4815081,40.63751111,0.10535976,2.200744157
4.154432165,3.677925063,34.63306362,18.02954056,5.161751786,93.06401318,40.40976096,0.110718037,2.210962183
3.393955537,4.208958201,55.05328123,30.51540191,5.945732286,181.4364103,36.69092584,0.149967044,2.227052242
5.145041172,5.444818259,47.38495878,35.13709941,2.135162244,75.02340801,37.93360065,0.142995363,2.25341854
6.531056475,7.076384869,53.95531289,56.38844771,4.401228585,248.1784479,32.53178998,0.174580022,2.263438492
4.664420371,4.554108817,52.71453321,38.49173502,5.655058005,217.6729942,24.4395234,0.230211623,2.277022295
4.284968609,4.69510856,65.96785761,60.37943153,3.044117438,183.8020804,44.260499,0.105008243,2.287815967
3.192209551,3.861345525,60.94631681,36.1044064,6.049127805,218.4001686,48.26216837,0.109977924,2.305740084
3.518104338,4.465406781,61.20748705,40.22111541,3.76109831,151.2755692,38.64442763,0.120292281,2.316559667
6.662212224,12.72664926,52.83734129,55.22309701,5.048021724,278.7673933,17.89182052,0.289675495,2.322580274
3.144485099,5.019417546,61.44296383,36.30234646,6.976266366,253.2548386,39.10738792,0.120003445,2.330945165
5.004260926,8.662962299,70.99537026,91.29226315,2.528161894,230.8016209,26.11709535,0.275485268,2.352268498
3.492074134,3.286503617,69.76507211,59.52284321,4.372632181,260.2714997,50.19549668,0.095303856,2.359113867
4.919153568,5.880765344,43.99505028,29.84230398,3.549183806,105.915822,38.88857269,0.138107876,2.374067867
4.180947386,4.266415283,60.25212901,45.96634941,3.14149952,144.4032646,45.0055562,0.105402584,2.389593786
3.44483062,4.302778056,63.3076255,43.04958866,4.336672179,186.6919535,43.6548267,0.120142798,2.405912062
2.163898678,3.810465099,68.94616755,35.32002602,6.59706407,233.0084746,38.74737657,0.115084764,2.416270401
6.849945448,11.58141397,44.72991511,42.63561232,4.471557714,190.6476012,22.33080713,0.23494365,2.424846816
7.322954937,14.21791125,48.7848681,52.53049433,5.175760975,271.8852826,22.73529768,0.339977084,2.4348472
4.77845748,2.729512298,46.01832946,31.11060475,4.183308102,130.1452449,45.04588227,0.114804992,2.440772374
3.10755777,3.885775122,64.05249059,40.1261823,5.56963251,223.4880895,49.02746062,0.104769943,2.447359045
3.844225582,2.924368184,52.70463804,31.71195813,4.479571062,142.05597,43.85447076,0.139899781,2.456934929
4.368005752,7.190767898,70.49214371,77.46849991,3.415423624,264.5877448,35.05196701,0.210422852,2.464368113
4.61627489,8.38295732,55.76731313,42.62709915,5.276788898,224.9342035,34.21074696,0.159243864,2.472443147
3.004326871,5.856050749,59.53784988,32.0948134,7.083263528,227.3360212,41.82867791,0.120252809,2.482455665
3.829394166,4.915422967,54.56218852,33.80955029,5.452879153,184.3593919,29.04675558,0.240406375,2.487408727
5.508705423,7.50651152,52.92687019,45.81019327,3.000617572,137.4588709,21.83347847,0.254968241,2.49422299
3.792121875,7.070458114,59.0400313,39.71695875,5.812099866,230.8389306,22.56142356,0.225185817,2.50619476
4.092493785,7.70227916,58.7840498,42.43202736,5.483497976,232.6759362,17.40948947,0.240152818,2.515273164
8.397080688,12.02482582,47.79357917,58.17352746,3.590140992,208.8511656,16.58215653,0.364889791,2.522016779
5.806854307,7.843288995,67.06515998,86.22706338,2.562838054,220.9859993,36.12960145,0.169809777,2.528394819
12.76905088,8.601339352,61.41132211,147.2220165,1.710774779,251.8637127,23.73792485,0.220440299,2.538079774
3.553166063,3.592276692,49.09839079,25.77145411,8.75960127,225.7476622,48.84224929,0.104233821,2.545571285
2.330071624,2.910226212,66.3002163,33.35181215,6.706601342,223.6773081,51.51952324,0.095154587,2.552872858
9.277877649,10.2599092,44.80973529,57.90874129,3.287623676,190.3821489,15.69853122,0.337012687,2.563086683
6.018579805,11.83007885,50.74948942,46.28344956,5.055676385,233.994143,24.37147685,0.30045518,2.574638289
3.834105769,3.961444367,61.19134322,43.80459089,3.524195649,154.3759486,26.75007837,0.195253991,2.580526975
3.085191299,4.89175961,61.62110486,35.88307623,6.41075462,230.0375967,23.71940212,0.180209176,2.591429741
4.526839681,8.289144572,66.72474319,66.12243046,4.201630855,277.822044,10.08249409,0.245016519,2.596634856
4.251079657,4.452358837,63.15844985,52.78230288,4.197550755,221.5563953,44.30935893,0.160003062,2.603517636
2.528808277,3.457209465,69.47638824,42.44365328,5.776587767,245.1794883,52.88455134,0.094863049,2.612753392
5.327409569,8.978885292,64.54934503,70.33364028,2.151694216,151.336487,32.90402253,0.218612931,2.622543956
2.99162888,2.618506486,52.669951,24.64770847,8.236041092,202.9995398,47.01237509,0.120328809,2.634671474
3.723418276,6.073496219,70.38869737,65.65959784,3.950707297,259.4018523,43.2050778,0.174677485,2.648282024
6.783515286,8.105309071,50.37353253,51.47281738,2.884473181,148.4719613,20.2539826,0.285816226,2.653118344
8.014660994,12.88880484,41.84773152,45.10043575,4.235074703,191.0037145,17.5964939,0.340209373,2.663533697
3.420322429,3.721743601,51.49903878,27.01635564,6.73031603,181.8286114,41.87807298,0.169909794,2.680607397
3.427234036,5.381563672,51.14037724,26.72582919,5.790341144,154.7516684,38.30897312,0.154253197,2.687724431
11.31598882,12.83267958,43.03937483,66.39365627,3.32031129,220.4476065,13.44985432,0.549958611,2.697692813
6.330910664,6.509528601,55.71528528,58.3462151,3.473490876,202.6650458,19.74318338,0.266002938,2.705711883
5.045344013,8.179052534,54.2577126,44.04773618,1.668986247,73.51506587,26.61753628,0.224556187,2.711734671
3.758100134,4.55242647,36.78221033,17.65322896,3.966299022,70.01798474,37.8899708,0.124397791,2.719560618
4.292238049,6.864556891,42.78666233,24.96184143,4.760893786,118.8406758,30.06964382,0.241847425,2.727847786
3.965388203,4.237475997,46.800045,26.53210831,8.003426884,212.3477889,27.04378367,0.224684287,2.734411297
2.133734923,3.912061831,69.18819116,35.27135993,5.54125261,195.4475153,41.50221178,0.135138278,2.74804367
4.067843437,6.796566999,58.29707235,41.37884117,3.508826479,145.1911736,32.6102878,0.195236309,2.758534401
4.8429964,8.318411579,42.67339668,28.05333404,4.195102775,117.6866195,20.41686624,0.33039433,2.763121438
3.876191932,5.426658304,55.8255296,35.87141811,2.322881652,83.32505897,20.38290331,0.206884327,2.77170371
8.914763176,7.287242159,38.17632393,44.04050341,0.555279399,24.45478426,6.545241265,1.886287146,13.08876008
9.033676708,8.170125549,38.73894288,45.53692189,0.684844,31.18568774,6.280448003,2.170513115,13.7874863
7.171338793,5.51366225,33.09315772,29.36582808,0.769794676,22.60565813,3.703509594,2.260798936,11.68676672
9.506550884,9.089418963,32.49657758,38.04809607,0.83698696,31.84576027,8.65713906,1.373088034,12.79656923
17.04306068,8.326867117,26.07278037,52.3971897,0.900590759,47.18842484,5.485686024,1.401228547,7.136365791
6.568273884,9.4360939,41.71628698,36.79099471,0.927457585,34.1220871,3.29436894,0.543041563,5.023799999
13.68104509,6.718209347,17.43761868,27.00039542,0.955161216,25.78973054,6.286827202,4.280793281,28.96329665
4.08527537,2.619613116,77.58948702,116.6451699,1,116.6451699,32.01614214,0.204766881,4.807300101
7.359826494,9.045949486,32.82009039,29.82463338,1,29.82463338,2.506817336,3.044537152,18.90810849
11.39543041,11.1528856,30.99439289,43.01184442,1,43.01184442,5.984597137,3.202945608,13.60699475
13.95525418,17.02617011,35.94155939,63.56920991,1,63.56920991,4.46920282,1.602645161,4.491839154
7.205806776,7.873291877,35.69638514,32.52935789,1.064469367,34.626505,7.868123544,1.226502505,11.86243976
7.718623417,7.287693644,28.01161035,25.79920731,1.093020383,28.19905946,2.3694063,0.665136629,3.318873781
12.13237487,7.926378306,33.89673907,51.21810959,1.11951988,57.3396919,10.02465483,0.977674915,6.381097039
5.759016733,5.194378304,32.13541213,22.72996546,1.139560734,25.90217612,8.496556911,0.595592893,5.827871159
9.589066331,9.072238928,45.15050034,60.56723492,1.184609325,71.74851128,11.94138784,0.715810576,5.428864475
12.75043066,7.314890033,42.24768945,72.76391901,1.195784298,87.00995185,8.713540946,0.534323551,3.501462286
12.69359428,8.538023793,43.70023765,76.21731799,1.210689166,92.27548115,11.35771169,0.590202687,4.503795654
9.455458267,5.516866801,34.47260303,40.78982114,1.246511887,50.84499694,7.46777846,1.254816243,9.448671346
8.439679874,9.050104457,47.67817757,58.23251924,1.263536348,73.57890473,15.00043333,0.87004011,6.167506216
4.566386214,7.308059263,46.19791649,29.91699042,1.280514549,38.30914149,11.63230635,0.469840861,5.522016189
5.690900236,8.636359683,42.79832066,33.10938055,1.296780907,42.93561255,9.077898736,0.740874474,9.243227276
5.472298869,8.036969589,45.40045368,34.86748694,1.313800349,45.8089165,5.819140373,1.263634882,11.463982
11.77796789,6.700667888,52.97557424,98.11844627,1.324870293,129.9942147,14.63538399,0.47600048,4.107240005
9.857397129,6.614690514,36.58701881,45.97585523,1.343914978,61.78764048,9.83772227,1.046801734,7.942114368
5.569009077,7.887973062,37.81492748,27.15649619,1.360178605,36.93768512,11.21664521,0.930842766,9.140823459
5.601868353,6.767511652,34.11195057,23.84125932,1.375396946,32.79119526,9.678704787,1.297852311,13.21878257
9.437922346,6.545296927,33.59610288,39.393155,1.389485221,54.73620667,11.80313417,0.869960635,6.666917705
4.822898455,7.545957365,39.94749699,25.38009102,1.399098935,35.50925832,13.67463408,0.87612931,10.15001688
11.95297378,8.928608274,52.12133967,96.54789261,1.413843127,136.5035743,15.25392617,0.356264256,3.162198368
4.755049453,8.288408525,40.81039852,25.79847485,1.424679524,36.75455887,10.40947983,1.167914916,12.80405673
10.40270557,6.560049384,43.23236826,61.44864675,1.441988645,88.60825088,12.86021608,0.495292872,3.520026983
4.310215562,5.467870148,37.11736067,20.49476968,1.458048154,29.8823611,8.836761349,1.363098833,15.41324112
6.568865791,8.470534966,49.75679177,48.7658312,1.472687145,71.81681271,18.84962467,0.604197216,5.11603545
4.453110878,6.898038009,39.47829594,23.0469063,1.483271094,34.18480991,15.51190339,1.123523546,10.95685238
6.428703215,8.848037657,60.80202464,72.28028421,1.498904651,108.3412542,22.05482341,0.494615526,4.089968384
5.4553413,5.588529166,36.23346621,25.11767195,1.508112354,37.88027136,6.640924443,0.86423516,5.547538748
13.01320545,10.06549147,15.16357774,22.1590869,1.531523714,33.93716707,6.668890868,2.937792717,13.07032353
4.790683083,7.371509926,40.03979857,25.2931785,1.55510209,39.33347475,7.620581565,0.95215594,10.07141055
4.118961454,6.328063869,43.67798229,24.71263404,1.574430657,38.90832865,18.12832431,0.93979059,11.43618645
8.757726332,5.448196401,28.76290455,30.20465198,1.588496678,47.97998933,15.6185685,1.653035246,15.40631838
4.819716206,5.647080565,32.45927887,19.26226274,1.60144308,30.84741738,15.93068663,1.285161827,14.06375874
12.07424002,8.075935704,30.42896986,44.56112528,1.615099359,71.97064487,12.93707415,1.63363064,11.63388974
13.15343381,9.862988665,16.39444174,24.31517058,1.635268481,39.76183207,5.739832537,2.321217945,8.982210466
4.326472985,5.916756781,40.96352689,23.6003537,1.650896335,38.96173741,14.8216282,0.731025177,8.419905981
3.936945229,5.977302044,40.1176308,20.8431274,1.672166993,34.85318966,6.600514016,0.717513315,7.716609701
5.793620844,5.059248735,22.24884491,14.89175563,1.688260337,25.14116038,10.83026255,2.838471108,28.83328154
4.636656848,8.429969533,59.19724593,48.86567825,1.714529762,83.78165969,19.53887441,0.417484726,4.264990839
11.04959383,4.106347637,50.93055032,85.52259876,1.726393776,147.6456822,31.10179146,0.349854034,3.360343947
3.909223774,6.965469621,43.01550793,22.9172199,1.746915942,40.03445678,22.48691122,0.927490355,11.95060973
4.669549985,7.552514905,54.65760492,41.37292464,1.759178376,72.78235439,26.08420229,0.383984468,3.821148717
4.03368171,5.539407635,43.99875126,24.47370581,1.776838169,43.48581462,10.07738088,1.145353814,11.83164999
4.380899907,4.67551329,54.11750727,38.05015812,1.792333133,68.19855912,17.85477772,0.849097896,10.31986732
3.29224851,5.569485938,63.08063847,40.7398277,1.810000368,73.73910313,30.2290266,0.611453312,7.365936071
4.3722355,6.934753352,40.5439339,23.49938855,1.81963322,42.76026806,16.45622494,1.223331621,15.313421
5.246551409,6.522571005,52.45987069,42.89865103,1.829390208,78.47837214,12.7842518,0.523671984,4.647000426
4.49317897,7.985839335,55.40707546,40.93466831,1.852120117,75.81592267,28.47137578,0.335229063,3.306626516
8.335486504,6.863140387,54.30284669,72.89294949,1.868170563,136.1764625,25.00704825,0.309712622,3.193853766
3.593501612,6.299444568,41.32627718,19.85417141,1.882817757,37.38178648,22.85830017,0.83481459,9.476008655
3.89741007,5.142832818,38.32421387,19.35638463,1.898390723,36.74598101,20.78645633,1.004034111,11.43165712
10.3170358,8.084654358,17.28571102,20.17264688,1.914971189,38.63003758,8.439707892,2.50362805,14.12576396
10.06310382,7.782168664,21.79651499,25.28507314,1.922020879,48.59843851,6.283376063,2.20199389,13.20169226
9.350643257,7.994040537,22.63893569,24.5028804,1.930742352,47.30874894,8.537985202,1.858689536,10.90142148
8.549601348,8.595738774,28.76444072,29.48872089,1.944295207,57.33477869,8.902888247,1.275442912,7.961774577
9.511342183,8.32705173,21.80508542,23.90905788,1.959445309,46.8484913,10.14053854,1.048408044,5.470708821
3.945870655,4.945291307,37.22764413,18.83749609,1.976350104,37.22948736,18.78216693,0.891229527,10.81229667
7.223929296,7.862024264,47.23865953,49.08236017,1.991457849,97.7454514,19.47345842,0.67139162,6.669800148
6.51403577,3.904701106,32.4750811,26.04956279,2.002865522,52.17377116,19.90003001,1.005749746,12.15678051
4.095860755,5.265874475,40.49493602,21.97587753,2.01667816,44.31827226,17.93143895,0.48834805,6.429538299
12.51966291,8.860324338,34.21609063,53.49186621,2.028135694,108.4887632,13.43331892,0.643440399,3.596548932
5.830287915,7.379421683,22.15081811,14.91289128,2.039131751,30.40935011,8.318301203,2.360327825,16.66640652
8.88587886,7.47087415,19.22340244,19.46820187,2.045658964,39.82530168,9.513927606,1.272410965,6.735736537
13.48705575,9.468288543,46.63304933,89.7154084,2.051708743,184.0698878,13.80078501,0.526344921,3.92841069
4.76008796,4.858271831,46.7190882,31.75933691,2.058687406,65.38254692,24.60019715,0.629128196,6.270834625
16.44477789,8.411121366,42.13420955,93.47395317,2.0671621,193.2258133,8.826113724,0.614213017,3.250857318
7.000907112,7.201523955,30.70967199,26.12820553,2.076478099,54.25464655,9.715385009,1.102726111,6.906506782
4.552357716,6.373004597,61.45395506,52.57992739,2.085945996,109.678889,23.17602052,0.34022514,3.576340408
8.691658946,8.340080828,37.54667773,41.97545796,2.09387581,87.89139603,6.286266849,0.953913315,5.366065536
12.14330908,9.833655958,20.70739397,28.84211429,2.115785629,61.02373094,6.542331195,1.686970497,7.794099619
4.424255964,8.207969656,63.92651728,56.81017047,2.12890636,120.9435332,23.81546779,0.466318299,4.675583455
8.428431017,7.195562898,22.66675737,22.11646455,2.138772572,47.30208778,11.55912885,2.158782509,16.95379396
9.661364235,8.490839263,34.54768321,41.79522638,2.147133188,89.73991767,13.96310049,0.607567937,4.39021791
14.21054745,6.695541119,7.771871457,12.18621256,2.155574091,26.26828406,5.598284159,5.785069373,18.44103718
11.7162435,10.07578403,23.72756543,32.35712062,2.161981786,69.95550542,7.017076137,1.418556722,7.03483871
14.05821292,8.099908852,32.00042166,55.19583672,2.170553754,119.8055306,10.93520034,0.801050173,3.557109251
7.967830153,7.498528908,25.37246045,23.74234592,2.179204129,51.73941825,12.70761609,1.44104189,10.46298046
3.226805659,5.00506392,41.68986995,18.05759649,2.192639611,39.59380135,25.45981543,1.170203182,17.45298531
11.25144074,8.864166688,22.18516122,28.82869319,2.200251597,63.43037822,2.468513807,1.280807308,5.594459391
4.631057036,6.129507362,50.73188081,35.59093798,2.212038057,78.7285093,30.81199002,0.694785921,5.8548365
5.320207984,7.109263573,64.57489183,70.31934837,2.220098996,156.1159147,22.15796349,0.280098649,2.863727259
11.63285683,9.424212919,31.86918534,45.44086489,2.231813207,101.4155224,5.44605147,1.179378919,5.487349072
3.255755547,4.71515362,41.93004055,18.37395075,2.243673472,41.22514586,25.23998392,0.507865902,7.890973598
6.55896243,5.894884525,28.29514613,22.185429,2.250827115,49.93556514,14.18693057,2.254184656,17.49525558
10.49868945,5.569003239,14.2978357,16.81166787,2.260679411,38.00579141,8.506099383,3.140936398,17.38686287
17.081926,7.211526748,25.47957758,51.14631067,2.272053258,116.2071418,8.943069038,1.485697418,8.00568678
5.092333937,7.291880011,22.53730912,13.27762542,2.285350267,30.3440248,12.86456787,1.824442929,12.92569921
6.697773472,8.526348201,36.0252245,30.60366099,2.293424712,70.18719239,16.73757978,1.16303096,11.09147092
7.147533872,7.736684771,30.34120471,26.28620768,2.301106156,60.48735433,15.07689407,0.701351872,5.550899639
6.680696733,4.05228386,43.54615972,39.89810996,2.306534743,92.02637681,20.03718186,0.480105075,5.077732847
5.489082063,7.422064918,23.22581806,14.80036937,2.31365281,34.24291619,9.688824754,1.684548224,13.18667873
8.096626762,7.73459463,36.80931795,38.07047695,2.32498794,88.51339977,11.48609625,0.628224988,4.251065827
7.278741711,6.082789843,20.67387503,17.25749229,2.334368391,40.28534452,10.09044217,1.074319729,6.030557512
14.05263771,5.835501787,35.1682056,62.21215186,2.343487723,145.7934141,12.52805945,0.782709538,5.147915687
11.37807349,9.735510712,31.99034585,44.65550239,2.349063682,104.8986189,8.138802973,0.857484368,5.077740383
6.528341859,7.968437105,37.25327437,31.19510616,2.356672074,73.51663553,13.90247521,1.018364054,8.397639152
6.51526996,7.611391899,38.71113051,32.80949858,2.36687177,77.65587599,6.784087034,1.170786433,5.577781901
9.022156683,5.061675187,50.99759521,69.99769739,2.375824791,166.3022648,17.88492754,0.419452591,5.581599352
4.330509272,5.487436761,49.41746281,31.76533126,2.389711419,75.90997485,33.2998862,0.290298963,3.299838999
8.301095022,7.888936748,36.53558705,38.64454176,2.403838698,92.89524494,15.05556498,0.604018505,4.726381267
5.044731887,5.202932752,69.88729368,86.55659987,2.410492042,208.6439951,45.82349183,0.175179208,3.382861902
4.791841889,6.831860958,24.88697863,13.96736648,2.427257559,33.90239587,13.01468425,1.081469873,8.693464815
4.029670189,4.550378019,51.26312102,31.56182906,2.446054864,77.20196549,15.88514575,0.736793418,9.802553764
18.70654235,9.33850174,6.662840333,13.73011015,2.461626471,33.79840259,7.278569088,6.206788303,17.71004107
10.99011928,9.392255937,19.63519553,24.63645813,2.471184341,60.88122955,7.999461693,1.023768866,5.031225783
3.760984301,4.279556969,57.46821086,37.0478031,2.478822951,91.83494462,5.617987006,0.176182402,2.989030328
4.088197258,5.401514644,51.71328308,32.54076547,2.482614587,80.78617903,32.08637753,0.185346346,3.194292153
5.971675241,7.206969025,34.01389962,25.32157576,2.49170712,63.09395061,14.12407709,0.738082608,5.786373785
5.666280266,6.592017201,33.95219295,23.97085,2.497260868,59.86146567,12.04816087,0.695050263,5.396439269
5.693932048,7.140266044,64.07900044,73.60915367,2.510365019,184.7858445,30.94560939,0.307218108,3.322812723
3.141384959,5.225580274,59.35975527,33.32153276,2.521897768,84.03349909,10.60697741,0.329736888,3.947459665
12.85569835,9.22215407,46.45890073,84.99662069,2.528658514,214.9274285,10.07779196,0.466570967,2.876296024
7.561528206,6.856294394,35.66278165,34.09296963,2.544632391,86.75407481,13.32374109,0.851566058,7.063946824
4.606607605,7.873235866,68.12312545,72.08493993,2.554426716,184.1356964,37.59825988,0.335061761,3.206868211
3.182405735,4.555417525,64.89953223,42.68522395,2.559717865,109.2621303,40.78124266,0.195572184,3.193317187
9.871202348,5.776989524,13.51528615,14.9078094,2.568490828,38.2905717,8.826901341,3.93011412,28.20058393
6.468887412,5.127173494,21.61585563,16.10559287,2.578625515,41.5302927,13.18500668,2.07300196,17.62859395
4.241474981,7.107508591,32.95780036,17.27880219,2.594223735,44.82507874,3.546394541,1.538255873,15.8388185
10.18150376,11.26671717,17.93250191,20.70256418,2.603089084,53.89061885,4.619860598,2.565548554,10.74318382
5.156858593,8.429978624,41.42512166,28.59102168,2.613404288,74.71989867,18.51534705,0.570600086,5.139821384
4.042933137,4.847505472,48.25207667,28.4631711,2.618764474,74.53834128,39.26050856,0.213765622,3.244981044
9.158201175,5.813232163,20.24003774,21.21724741,2.625046198,55.69625464,13.84162091,2.196621609,17.44565324
5.368500814,7.380521115,39.79156962,28.09544011,2.63411395,74.00659073,19.45817938,0.57896675,6.578572769
3.565279619,3.368669714,51.78839139,28.45512539,2.646583026,75.30885186,27.71570735,0.289119466,3.357084632
12.32036285,6.584680567,29.45680741,43.72010237,2.660202645,116.304332,10.75901895,1.084357353,6.061593716
12.35476444,5.881247046,26.3489136,38.44828168,2.671225503,102.7040306,11.12193209,1.425045987,9.254217092
8.040095888,10.58783472,38.18496455,39.73182215,2.677404003,106.3781397,12.8260915,0.42312425,3.066333534
6.323344193,7.983816505,46.65077968,42.08874122,2.687532353,113.1148537,18.50999365,0.361893376,3.865114101
4.025412249,3.465907748,45.94922869,26.1446555,2.704270253,70.70221413,21.12921607,0.842895201,12.80404287
4.80594166,7.915403158,41.27703981,26.50694814,2.716352182,72.00220642,17.1845033,0.967406221,7.930846862
9.149884997,11.3218549,21.49624811,22.64173119,2.724033275,61.67682916,7.508130886,1.396449063,6.740998855
6.146688615,4.784586128,22.02942526,15.62688632,2.731007155,42.67713835,13.70635115,2.322094663,19.08286978
4.649489397,4.787019266,55.87717952,43.11131512,2.737423826,118.0139412,32.88161924,0.544288816,5.060001563
6.264077852,5.454921692,23.91998985,17.45765604,2.750015586,48.00882621,14.48324906,0.706924953,4.386083616
6.916061045,5.336700515,17.26940942,13.50924468,2.76053258,37.29271007,10.77602707,2.934983159,29.8412526
9.790430752,8.256253408,19.48140949,21.76117621,2.768064144,60.23633161,7.856759898,1.867043162,11.03798136
20.81167789,12.90667087,14.07469566,32.78416545,2.776980209,91.04097862,3.234401252,2.679653738,7.696291316
5.754972746,6.036099136,33.36194178,23.8083905,2.783787323,66.27749567,14.10669566,1.183958679,10.65227297
10.26539119,10.76043906,31.31494193,39.2392649,2.793818074,109.6273675,6.437156356,1.136955796,4.275797236
12.64547923,6.883454394,34.94269965,55.51587622,2.80223799,155.5686974,10.8037633,0.905259238,5.787943895
2.338494111,3.20123552,43.13972561,13.76876659,2.809878227,38.68855746,38.45450258,0.39419356,5.494826416
7.362579107,10.62995026,40.63469125,39.69861155,2.818765508,111.901077,16.56907795,0.429071214,3.435278327
4.777647999,7.454874006,42.52554551,27.53183808,2.826583639,77.82104308,21.28588474,0.36817424,4.084784629
12.74522322,6.220580914,33.70095862,53.4090565,2.832819083,151.2981945,12.84240035,0.870184427,5.376590006
10.25213753,8.124542678,15.54635107,17.92029165,2.838058527,50.85883652,9.122209881,4.000673532,19.7574162
3.126983877,3.165957236,51.87078146,25.03098354,2.847615618,71.27861965,48.63997476,0.531202958,7.105374955
10.8320363,9.966129892,14.47798251,17.57353267,2.852215601,50.12350406,6.865809409,3.297747661,17.70279583
9.321550095,8.016984359,20.86720469,22.32693226,2.859405948,63.84176291,11.78549863,0.818306837,4.520198194
9.437842167,10.71232421,34.86819702,41.31913666,2.869540855,118.5669507,11.05743209,0.614392937,3.641730555
10.1578425,7.634122394,11.23613112,12.67924524,2.879949447,36.51558531,6.56373688,4.39272775,24.67601195
3.98364528,4.567333554,19.40144872,8.815159281,2.890152684,25.47715626,13.4936324,3.525211571,38.48206608
6.642398938,4.572504808,10.4939953,7.73067941,2.893526358,22.36892464,10.5659121,4.152954038,33.15492569
21.24856811,15.09629079,15.34798043,36.64404207,2.899735945,106.2580459,3.943048828,2.620407607,9.967389401
4.789004248,5.791130626,64.67700526,63.59024647,2.906171758,184.8041784,42.3289325,0.225150435,2.897614621
4.45174467,7.422717508,43.76476757,26.79035766,2.914499886,78.08049433,24.59952201,0.49262132,4.905060668
7.705959049,9.233039169,19.91156235,17.53811195,2.92247295,51.25465778,11.85145914,2.17886718,16.06273341
11.46459338,13.48774128,21.9300764,29.00148151,2.929565176,84.96173029,7.255479323,0.930848638,3.24260617
12.85669613,14.8635935,15.00606037,21.65436305,2.93707664,63.60052387,4.614036283,2.023078411,6.752207644
18.04350683,11.16621598,18.08251893,37.01697448,2.945763235,109.0432425,9.325114947,1.657703786,6.229405375
8.241506566,10.45945966,20.27124081,19.12553798,2.953864468,56.49424707,9.310361601,1.40397282,7.850708834
21.28639171,14.27011578,11.73933498,27.79330789,2.958561742,82.22821741,3.564488597,2.107317525,4.826144717
2.825887232,4.28942296,73.40497246,59.57877121,2.965876902,176.7033014,64.15706022,0.119955215,3.920241726
3.333544831,4.805830959,67.44104354,50.41957469,2.970931624,149.7931089,44.7196939,0.274841197,4.034616307
7.350857011,9.449873342,22.4262417,19.061576,2.976400979,56.73489347,11.55993849,0.758039859,4.920441535
7.372253784,5.150000634,28.32271936,24.9651141,2.980615224,74.41139917,14.09663841,1.208032438,8.932212632
4.35431364,5.519964018,39.01048857,22.16314234,2.985760474,66.17383436,25.95569639,0.755445838,8.162700704
9.036080591,11.78596609,16.98565717,17.34243236,2.993961991,51.92258331,8.118692157,1.747384695,9.212738054
9.415069141,12.36972858,15.58756626,16.50298874,2.998445165,49.4833068,5.967078702,2.753380338,11.94887534
9.10059938,10.71524836,13.63431432,13.86973486,3.002684577,41.64643896,4.683759225,3.670862561,19.79832627
5.451815483,5.250023804,30.01400511,19.78816459,3.012445434,59.61076606,16.18140439,1.13494167,11.09469889
7.441360459,11.15562731,26.96305734,23.78512937,3.018175108,71.78768538,11.04789536,0.944743652,6.481419397
16.24670537,8.322150564,7.96261676,14.27864425,3.025404056,43.19866824,5.006053298,2.854226103,5.788488841
5.78837074,9.936089503,44.28717827,35.47553082,3.030997527,107.5262462,25.29302268,0.691608378,4.697872316
8.630865509,10.91712521,16.82797347,16.40169326,3.033165437,49.74904912,7.950702876,1.043348154,4.98738406
6.85191307,6.603308926,17.87415616,13.88392359,3.038565264,42.18720794,9.431093316,1.214055497,7.814506152
13.5859333,13.95235738,18.17064895,28.0174575,3.042103037,85.23199256,4.255235335,1.439168218,4.289442304
20.98107472,14.33307159,12.20439234,28.51279686,3.047698543,86.89840946,8.4461392,2.598362843,7.700352046
8.714321073,9.993035407,43.59717967,52.13609915,3.053616181,159.203636,14.3166444,0.674561267,3.943358909
5.831896982,6.677691168,42.70713709,33.82153727,3.060078314,103.4965527,22.21509223,0.340341561,3.624089055
9.176435206,6.862768827,14.57910928,14.99614007,3.068044638,46.00882713,7.053112797,3.352209697,21.50556156
3.992691403,7.389882325,49.01467322,28.87401618,3.073765385,88.75195145,13.23823341,0.5547302,4.562096182
3.4601077,3.681030249,48.92520592,24.94374387,3.079702186,76.81930253,35.84953134,0.184616566,3.254388429
11.81205629,14.98634709,19.20674756,25.85501243,3.083456051,79.72279455,7.53773969,1.188533425,3.784657803
15.19873169,13.46325034,18.38318992,31.73632472,3.087891381,97.99832357,8.975796262,2.384952094,13.66922758
3.049777936,3.919695963,50.81477752,23.5077018,3.093086331,72.71135114,45.03706226,0.419466718,6.307000204
8.609903,4.810204341,28.20231498,29.00970145,3.097688148,89.86300836,17.11067348,1.291004063,11.31590958
5.179927152,4.374615787,27.00208852,16.58473497,3.100919533,51.42792862,15.47940616,0.819689733,6.371533331
4.435047484,7.853777295,24.85688359,12.90959164,3.105952692,40.0965809,13.51374521,1.564686025,10.8752324
13.94400549,15.74351061,19.42482598,30.89600341,3.109293103,96.0647303,7.194819482,1.293251656,3.963821807
12.46540152,14.37654764,15.0203961,21.01631702,3.112492204,65.41312288,6.210637492,2.378007048,7.852850158
4.285759642,4.223278772,52.28302746,34.81972569,3.118602683,108.58889,38.71646807,0.295840794,3.931703194
18.41932123,15.0346115,21.12228431,44.70898743,3.124452823,139.691122,8.176225822,1.350446699,4.005406091
5.609567945,9.102576468,33.9174347,23.69986994,3.133333062,74.25958604,18.76346891,0.452996193,4.310805521
9.571391557,8.491296144,16.28880957,17.57307429,3.141088455,55.19858076,6.414137369,2.063490967,10.75094355
4.058512388,6.192008934,41.60860933,22.64715462,3.148585609,71.30650514,26.63835585,0.355899821,3.721137835
21.31005546,15.45251269,13.54296404,32.25156124,3.160382076,101.927256,7.708748154,2.18955158,5.871653757
19.7431467,14.17110263,12.21119767,26.84590496,3.169498698,85.08806083,8.57012575,2.555169038,6.819821995
9.611859607,7.490013649,27.22040577,31.06502977,3.175626319,98.65092615,14.98219367,1.266521572,9.592544272
4.951102901,7.384870614,49.018882,35.81029014,3.183769424,114.0117068,26.13207266,0.870222271,8.364897404
11.52918511,11.23762688,23.00973262,30.76348172,3.190378372,98.14714675,12.65686329,1.211316432,6.732097684
2.444887799,2.769379171,39.0104412,12.4442815,3.200564835,39.82872977,28.72347398,0.834703202,12.72334094
6.862313064,8.254414222,35.57642478,30.84204564,3.207529743,98.92677873,16.09572381,0.460363373,4.020593108
5.279266724,10.02171555,61.28116053,60.54009443,3.21969688,194.9207531,24.77182375,0.279581836,2.872205861
15.42693972,10.2458569,24.33987139,43.84694759,3.224530232,141.3858081,11.42464224,1.357003844,5.600582244
15.49020578,17.36069503,28.58291915,53.02722334,3.233682186,171.4731875,7.933309257,1.09969832,4.521926424
5.069408916,8.810563194,54.52226389,44.69163052,3.238642469,144.7402126,34.30930411,0.295164544,3.414592725
7.148002669,9.826190918,25.79020277,21.7019444,3.246350764,70.45212378,9.273099198,1.21533946,8.602850921
8.543669045,12.01809519,36.967122,40.40360346,3.254077794,131.4764688,8.303056205,0.744339182,3.925773817
2.861419731,3.651012786,61.80903859,33.54308189,3.258681062,109.3062057,48.86284504,0.189716655,3.668341323
3.132911295,4.916505864,66.2301076,44.69469756,3.267963148,146.0606246,43.73656513,0.43000422,5.30081978
10.20989629,11.89309986,29.92084673,36.91933662,3.276615283,120.9704626,13.41699225,0.570457699,3.758644645
9.704947479,10.27888439,29.06555418,33.89190973,3.286020224,111.3695008,11.91837937,0.697462931,3.652705956
9.541677758,7.748340394,48.70077318,68.24393425,3.294982017,224.8625361,16.86932711,0.42551234,3.602661827
2.858543038,4.902970311,33.94086696,12.08773121,3.302824001,39.92364876,23.00220899,0.711936883,7.623528101
4.364703689,5.572424674,38.41625258,21.74885535,3.316799166,72.13658529,19.7472289,0.349592866,3.571311651
3.742370172,6.869834011,47.84349084,25.97192501,3.326520819,86.39614926,19.06340784,0.521153941,5.088563478
15.71096324,10.5120001,25.39543484,46.86363929,3.333828724,156.2353468,10.01918589,1.221080645,6.063278133
4.415019907,3.437962433,48.87877432,31.77563342,3.346420108,106.3346186,43.66933508,0.335677464,4.420472521
2.352458538,3.215452902,56.09987302,21.99624341,3.358490459,73.87417362,48.67304532,0.294447848,5.802699605
4.981989524,5.6529549,64.43175831,65.4269494,3.371762407,220.6041284,38.83768203,0.305105214,2.942553234
14.57719278,17.69329395,31.46825217,56.057376,3.377203746,189.3171802,8.139796586,0.720508524,2.934192335
13.64820784,13.76981174,30.83267965,51.18608925,3.382559854,173.1400106,10.36518281,0.601035698,3.587930474
9.915184735,13.01548563,31.52276178,38.21089307,3.394151353,129.6935544,11.44229785,0.515226027,3.106065564
6.708856511,6.916876091,32.35979942,26.70963115,3.410757994,91.10008799,18.45770579,0.75292666,7.268404237
13.47551626,13.35671216,35.33353565,60.02354355,3.426265909,205.656621,13.05848905,0.724417726,3.610269025
3.06425929,4.841846389,31.8084604,11.94149358,3.438732507,41.06360217,22.63677292,0.656397915,7.192668685
6.247637266,8.815146416,57.99107399,62.79946001,3.448740715,216.5790546,23.93874206,0.47567359,4.034337829
8.462412604,11.09594487,29.02627578,29.50499922,3.458161368,102.0330485,11.69747496,1.027454368,7.171041075
4.209857077,7.334500688,50.61898469,32.22411771,3.470506208,111.8340006,32.53641673,0.241233364,3.159529613
3.744657571,6.759935273,52.96882027,31.1878848,3.486021074,108.7216237,39.27814798,0.329584658,4.228471692
4.313137242,5.330165095,66.51483008,62.37042839,3.499739008,218.2802212,29.17906046,0.205577065,2.81317641
3.778340288,4.137666498,60.66355042,42.24121555,3.514923495,148.474641,44.0947217,0.344990002,5.868841634
8.334233955,11.02836646,42.51344166,48.00677854,3.533163523,169.6157988,16.60053316,0.43502945,3.271955018
4.709201832,7.734322559,35.51735892,21.11900568,3.545060534,74.86815355,28.81549428,0.40426785,4.438637426
3.078517925,4.468502813,30.75911851,11.51198375,3.557960036,40.95917811,22.15751162,0.963931897,10.96411002
8.424334909,12.83086318,30.86604092,31.63634879,3.580807337,113.2836699,10.55741705,0.649292846,3.57128801
6.236331618,7.055667701,55.53122358,57.07972614,3.592803734,205.0762532,22.5579702,0.331051005,2.998103897
3.875113655,5.978653538,68.46269185,61.69330833,3.607601309,222.5648599,38.47133009,0.18499797,2.935312394
7.320474109,7.273126673,36.79136522,34.39851599,3.621389066,124.5704097,20.07065006,0.734325935,7.181328365
4.33450697,3.537798609,61.6744294,50.52594185,3.641013559,183.9656394,48.01169815,0.215321252,4.327565454
6.601577463,9.143709351,35.53586464,29.62582809,3.662514092,108.5050129,15.23178774,0.409832245,3.25251676
6.883003204,11.24419508,45.94546617,44.69855271,3.681354205,164.551205,12.16620918,0.53489668,3.812986234
4.172626074,6.99017127,22.53593277,10.87886367,3.696661633,40.21547795,2.696288545,1.792460839,6.957170683
4.081061267,6.7534139,50.03444646,30.59636014,3.712038353,113.5748623,29.46436257,0.22917656,3.045117748
3.121926585,3.215218339,58.70686093,32.27076997,3.72613287,120.2451767,33.5032356,0.235092714,5.146882593
4.905005622,6.881553835,51.30008582,38.46859224,3.765714109,144.8617205,36.97504896,0.399995203,4.132295206
7.760491453,10.70037448,43.35393211,46.03640419,3.780874394,174.0578618,16.60471826,0.356490646,2.839460232
3.411872664,3.631926379,53.10315852,28.55525198,3.79997384,108.5092105,45.0370245,0.209811005,3.202508859
7.130000725,10.23111929,41.11672701,39.10379712,3.815839113,149.2137985,14.3692654,0.904486404,6.889779191
4.010295922,7.083247738,56.58718925,38.19532648,3.843563272,146.806154,28.21823314,0.239619217,3.093957885
4.459433899,5.960345074,52.63435475,36.69349607,3.859120677,141.6046294,27.74406063,0.265027101,3.371354704
6.352185151,5.430519975,47.48531442,43.53385034,3.87683731,168.7736553,24.21013126,0.437648749,4.694303587
4.698417717,6.51187147,51.69040917,37.36724463,3.905433628,145.9352938,27.66757247,0.239034764,3.335032684
5.608904629,7.998765614,45.87671945,36.33714781,3.929363927,142.7818778,25.16869712,0.394540375,3.35376737
4.162768522,5.300333251,53.61501542,35.49585586,3.950511857,140.2267995,30.5462095,0.265315121,3.519478963
3.442056959,4.563807736,40.42088868,18.41968921,3.962853763,72.9945347,37.42086712,0.28576879,3.691344399
3.780757286,6.149567393,49.4910526,27.80497045,3.980171874,110.6685613,36.02418974,0.489740918,5.859006268
4.019866601,2.743558833,46.74597663,26.84580663,4.008043281,107.5991549,40.01870222,0.13639405,3.171185049
3.089722734,4.73161837,44.53466061,19.10049593,4.025604563,76.89104359,31.47964061,0.540914032,6.528392228
3.631827854,3.165874188,48.60691662,25.88988207,4.035540338,104.4796634,44.11983092,0.215082148,3.375298067
3.854765491,3.647394598,55.35891038,35.05537525,4.052350909,142.0566817,47.70646824,0.220129694,3.170220003
4.422932717,3.254386915,50.70687147,33.96118366,4.065591821,138.0723105,46.38860401,0.125623284,2.88244268
4.043538852,7.398252792,62.60075046,49.0153002,4.083675092,200.1625605,12.37557644,0.314722866,3.632888445
3.534727654,4.637088877,49.91025768,26.38403519,4.114316857,108.5522807,42.36462878,0.188602335,3.218666063
3.397420284,5.339536568,66.7732845,49.74133201,4.140798756,205.9688457,52.98558977,0.21959139,3.936943015
4.238382329,2.300904391,39.5221029,21.96978407,4.158112483,91.35283341,49.98692893,0.375388563,4.520063778
2.291356462,3.93073454,72.49523509,45.64826759,4.174148979,190.5426696,56.90606259,0.114772019,3.350267708
4.896329873,2.802968504,45.38820606,31.18428705,4.198998219,130.9427658,48.21757256,0.180366359,2.941630081
5.196814235,2.778379132,51.04334777,40.3849716,4.223465814,170.5645469,42.84430244,0.195099588,3.062056962
4.24297485,5.007986148,43.85382046,25.61355781,4.246460417,108.7669594,33.19938949,0.197309616,3.051981073
2.710376509,4.692689065,47.08345498,18.31563593,4.263793328,78.09408629,36.24578164,0.234350664,4.225707446
7.406176464,11.28295074,47.60694107,50.97404794,4.288903556,218.6227755,19.52864254,0.409636649,3.087721531
4.499207029,5.368576669,49.49608351,33.09457687,4.30898295,142.6039675,34.08905751,0.299618308,4.262312754
4.604378199,7.621107504,43.80999979,27.75272144,4.334052046,120.2817391,25.09998482,0.245126939,3.102121219
8.603954727,13.73238707,47.60896609,59.22212824,4.366773491,258.6096197,18.95366369,0.420418323,2.98149522
2.67910195,3.836495204,72.04883219,51.95818783,4.386280135,227.9031671,51.95309378,0.179788779,3.257359263
4.777633413,7.147681494,41.72210733,26.76652033,4.431690317,118.620929,26.81705969,0.251980493,2.85086578
3.99601954,4.804411552,46.26810784,26.24447771,4.473835291,117.4134706,27.8341177,0.325946095,3.748624809
3.934134051,6.147533108,58.50784919,40.34997443,4.494989336,181.3727048,31.96761527,0.220408378,3.25992176
5.114242266,9.590822916,56.44742838,48.45212132,4.537744088,219.8633271,32.68033207,0.279708283,2.97435018
2.820383861,3.381868989,70.1548806,49.10060211,4.58091724,224.9257947,56.29001296,0.095056917,2.888750914
3.608440916,3.916432824,65.42419881,49.57635084,4.621893496,229.1366135,44.81110126,0.16065558,2.819119559
2.406188595,2.972818757,58.36674384,24.54288704,4.684362418,114.9677777,50.67227791,0.124657345,3.118459912
3.092153034,5.604199385,52.16319684,25.01396856,4.714244705,117.9219688,32.51016509,0.184892409,2.847317338
2.885282232,3.875699901,68.36147845,45.69823949,4.796400043,219.1870378,50.60230064,0.238231587,3.841722587
2.75740615,4.898432013,70.29556049,48.37585785,4.848333435,234.542289,40.1332009,0.310051372,4.444739277
3.083147247,3.582920796,38.10696515,15.19338005,4.88582376,74.23217723,30.95178856,0.413667567,5.335379098
2.905778403,4.27966888,68.04206606,45.28470287,4.932049093,223.3463777,44.65766558,0.436889788,5.5292464
2.280765512,2.679514792,64.12206451,29.5413903,4.985163801,147.2686696,53.70369094,0.1402918,3.371353121
4.056143733,3.902549592,39.52503371,21.02733574,5.045069503,106.0843703,37.42752695,0.305208931,4.138823764
2.137916674,3.978983339,72.06154488,41.49390215,5.063532818,210.1057353,53.32523569,0.134978913,3.011838808
3.023624491,4.842345356,70.01551989,52.24058115,5.124176076,267.6899361,40.8323775,0.388404365,4.479225266
2.848775694,2.845291889,57.83331019,28.46042293,5.158799896,146.8216268,51.31016364,0.139781514,3.23013547
4.004711089,2.329407229,44.05309192,24.34409121,5.206592208,126.7497556,51.63407317,0.123878345,2.806380932
2.734534056,3.670203545,64.11318299,35.40480574,5.232576475,185.2583536,45.37732433,0.150525002,2.899930625
2.170817716,3.731760849,74.78281837,50.14281775,5.293910117,265.4515702,56.56794736,0.20008091,4.202432135
3.358041505,3.986061834,44.60497467,20.81024811,5.338716164,111.1000079,41.36343813,0.171326091,3.40150928
3.683748301,3.899183784,40.26100446,19.60189133,5.4171759,106.1868933,41.14828643,0.264755164,4.109361179
2.605282569,4.516451024,59.72335433,28.03922684,5.470352833,153.384464,39.07665588,0.165044494,3.269059707
2.049761051,3.199571346,74.83120041,47.50492619,5.555082991,263.8938075,53.35659894,0.099809144,2.904748014
2.819229288,4.696242233,61.40957907,32.50222553,5.652272555,183.7114373,44.90934526,0.139962857,3.271686495
2.789652745,3.728775447,61.79760438,32.68612328,5.726186773,187.1668468,56.27157283,0.119717978,3.478068952
4.065904248,3.965901525,42.36641305,23.30001367,5.820769327,135.6240049,44.96101493,0.234110601,3.023063446
3.789446349,7.274222286,53.57271381,32.26263943,5.901099299,190.3850389,38.84211079,0.154845687,2.841107941
3.904892793,4.070182437,49.85961205,29.094795,6.00623416,174.7501516,41.37160337,0.315368327,3.615401144
3.699512092,4.891199789,46.99687,24.92418048,6.089471901,151.7750967,38.05393867,0.334925537,3.724004009
3.29807129,2.979184647,37.79299313,16.06987713,6.139419568,98.65971814,44.1364883,0.255851709,3.6934628
2.838527024,2.674859758,58.49830531,29.10212845,6.222751929,181.0953259,50.91466639,0.125055556,3.359559661
2.45717808,1.576663263,45.21855422,15.55713991,6.305534153,98.09607701,55.94434889,0.187104861,4.160658887
2.629002368,4.198509225,54.66879013,23.30300141,6.438519334,150.0368251,49.65677737,0.14535086,3.591326488
21.85399628,17.67697168,4.111001797,9.869199611,6.525131919,64.3978294,4.21138624,5.001293297,12.46821516
3.414300228,2.999248692,43.26529667,20.1914656,6.70404151,135.3644235,34.84106284,0.22409897,2.799487196
2.992658172,1.9894753,52.9635133,24.9199553,6.883242516,171.5300958,53.28626875,0.370062715,5.50180094
3.270825803,3.75458338,54.86231376,29.20056058,7.014771353,204.8352558,45.33569437,0.215123479,3.124158991
3.400561938,3.140449231,51.48891552,26.85053297,7.338859947,197.052301,51.20836507,0.135351086,2.87800398
3.059415995,3.573603959,50.44080121,23.27018732,7.593462593,176.7012969,45.92812304,0.304945769,4.31564215
2.296732542,2.148581587,66.11579184,32.58918943,7.861187392,256.189725,59.72219331,0.214887941,3.868926601
3.055067185,5.058195568,59.31539299,32.3487902,8.026303825,259.6412185,46.19396026,0.421791399,5.615238487
3.771675333,2.573224286,47.03736481,25.44638849,8.801768111,223.9732108,34.03312532,0.369708116,3.809326124
1.45243998,1.772388196,70.02948361,25.11354226,10.8021878,271.2811998,47.96271649,0.110714609,3.306603498